<?xml version="1.0" encoding="UTF-8"?>
<robot generator="Robot 7.1 (Python 3.13.0 on win32)" generated="2024-10-15T11:06:43.826279" rpa="false" schemaversion="5">
<suite id="s1" name="Preenchimento Incorreto" source="c:\Users\92006\Desktop\Logica\Curso_Robot\testes\preenchimento_incorreto.robot">
<test id="s1-t1" name="Verificar se quando um campo obrigatório não for preenchido corretamente o sistema exibe uma mensagem de campo obrigatório" line="10">
<kw name="Dado que eu acesse o Organo" type="SETUP">
<msg time="2024-10-15T11:06:44.974765" level="FAIL">No keyword with name 'Dado que eu acesse o Organo' found.</msg>
<status status="FAIL" start="2024-10-15T11:06:44.974407" elapsed="0.010601">No keyword with name 'Dado que eu acesse o Organo' found.</status>
</kw>
<kw name="Fechar o navegador" type="TEARDOWN">
<msg time="2024-10-15T11:06:44.994701" level="FAIL">No keyword with name 'Fechar o navegador' found.</msg>
<status status="FAIL" start="2024-10-15T11:06:44.994295" elapsed="0.000772">No keyword with name 'Fechar o navegador' found.</status>
</kw>
<status status="FAIL" start="2024-10-15T11:06:44.963720" elapsed="0.035121">Setup failed:
No keyword with name 'Dado que eu acesse o Organo' found.

Also teardown failed:
No keyword with name 'Fechar o navegador' found.</status>
</test>
<status status="FAIL" start="2024-10-15T11:06:43.838411" elapsed="1.167465"/>
</suite>
<statistics>
<total>
<stat pass="0" fail="1" skip="0">All Tests</stat>
</total>
<tag>
</tag>
<suite>
<stat pass="0" fail="1" skip="0" id="s1" name="Preenchimento Incorreto">Preenchimento Incorreto</stat>
</suite>
</statistics>
<errors>
<msg time="2024-10-15T11:06:44.938493" level="ERROR">Error in file 'c:\Users\92006\Desktop\Logica\Curso_Robot\resources\main.robot' on line 3: Getting keyword names from library 'FakerLibrary' failed: Initializing library 'FakerLibrary' with arguments [ Locale=pt_BR ] failed: AttributeError: Invalid configuration for faker locale `Locale=pt_BR`
Traceback (most recent call last):
  File "C:\Users\92006\AppData\Local\Programs\Python\Python313\Lib\site-packages\FakerLibrary\keywords.py", line 42, in __init__
    self._fake = faker.factory.Factory.create(locale, providers)
                 ~~~~~~~~~~~~~~~~~~~~~~~~~~~~^^^^^^^^^^^^^^^^^^^
  File "C:\Users\92006\AppData\Local\Programs\Python\Python313\Lib\site-packages\faker\factory.py", line 44, in create
    raise AttributeError(msg)
AttributeError: Invalid configuration for faker locale `Locale=pt_BR`</msg>
<msg time="2024-10-15T11:06:44.945659" level="ERROR">Error in file 'c:\Users\92006\Desktop\Logica\Curso_Robot\resources\main.robot' on line 4: Resource file 'shared\setup_teardown.robot' does not exist.</msg>
</errors>
</robot>
